{
  "timestamp": "2025-07-17T13:38:38.441577",
  "backend_tests": {
    "exit_code": 5,
    "stdout": "============================= test session starts =============================\nplatform win32 -- Python 3.13.4, pytest-8.3.5, pluggy-1.5.0\nrootdir: C:\\cursor\\collective-memory\nplugins: anyio-4.9.0, aiohttp-1.1.0, asyncio-1.0.0, base-url-2.1.0, cov-6.2.1, django-4.11.1, playwright-0.7.0\nasyncio: mode=Mode.STRICT, asyncio_default_fixture_loop_scope=None, asyncio_default_test_loop_scope=function\ncollected 0 items\n\nWARNING: Failed to generate report: No data to report.\n\n\n=============================== tests coverage ================================\n_______________ coverage: platform win32, python 3.13.4-final-0 _______________\n\n============================ no tests ran in 0.12s ============================\n",
    "stderr": "C:\\Users\\hp\\AppData\\Local\\Programs\\Python\\Python313\\Lib\\site-packages\\pytest_asyncio\\plugin.py:208: PytestDeprecationWarning: The configuration option \"asyncio_default_fixture_loop_scope\" is unset.\nThe event loop scope for asynchronous fixtures will default to the fixture caching scope. Future versions of pytest-asyncio will default the loop scope for asynchronous fixtures to function scope. Set the default fixture loop scope explicitly in order to avoid unexpected behavior in the future. Valid fixture loop scopes are: \"function\", \"class\", \"module\", \"package\", \"session\"\n\n  warnings.warn(PytestDeprecationWarning(_DEFAULT_FIXTURE_LOOP_SCOPE_UNSET))\nC:\\Users\\hp\\AppData\\Local\\Programs\\Python\\Python313\\Lib\\site-packages\\coverage\\control.py:915: CoverageWarning: No data was collected. (no-data-collected)\n  self._warn(\"No data was collected.\", slug=\"no-data-collected\")\nC:\\Users\\hp\\AppData\\Local\\Programs\\Python\\Python313\\Lib\\site-packages\\pytest_cov\\plugin.py:358: CovReportWarning: Failed to generate report: No data to report.\n\n  warnings.warn(CovReportWarning(message), stacklevel=1)\n"
  },
  "frontend_tests": {
    "error": "[WinError 2] Sistem belirtilen dosyayı bulamıyor"
  },
  "e2e_tests": {}
}